<?xml version="1.0"?>

<robot name="fourdof">

  <!-- ******************************************************** -->
  <!-- ******************* Kinematic Chain ******************** -->
  <!-- ******************************************************** -->
  <!-- Note the 'origin' tag in the joints defines the shift and
       reorientation, i.e. the transform.  For moving joints, this
       happens before the continuous joint rotates around 'axis'. -->

  <!-- World can't take a visual element (at least in Gazebo). -->
  <link name="world"/>

  <joint name="tableplacement" type="fixed">
    <parent link="world"/>
    <child  link="table"/>
    <origin xyz="0 0 0" rpy="0 0 0"/>
  </joint>

  <link name="table">
    <visual>
      <origin xyz="0.0 0.0 0.0" rpy="-1.5708 0 0"/>
      <geometry>
        <mesh filename="package://snakes_and_ladders/meshes/Table.STL"
	      scale="0.001 0.001 0.001"/>
      </geometry>
      <material name="wood"/>
    </visual>
  </link>

  <joint name="placement" type="fixed">
    <parent link="table"/>
    <child  link="baseplate"/>
    <origin xyz="0.748 0.01 0.0" rpy="0 0 0"/>			<!-- WHERE IS THE BASE .748 -->
  </joint>

  <!-- BASE PLATE: Shift across the base plate to the base motor. --> 
  <link name="baseplate">
    <visual>
      <origin xyz="0.0 0.025 0.0125" rpy="0 0 0"/>
      <geometry>
	<box size="0.2 0.1 0.0230"/>
      </geometry>
      <material name="wood"/>
    </visual>
  </link>

  <joint name="baseplate" type="fixed">
    <parent link="baseplate"/>
    <child  link="basemotor"/>
    <origin xyz="0 0 0.0230" rpy="0 0 0"/>
  </joint>

  <!-- BASE MOTOR: Thickness: X5 = 31.1mm, X8 = 45.1mm -->
  <link name="basemotor">
    <visual>
      <origin xyz="0.0 0.0 0.0" rpy="0 0 -1.5708"/>
      <geometry>
        <mesh filename="package://snakes_and_ladders/meshes/X8.stl"
	      scale="0.001 0.001 0.001"/>
      </geometry>
      <material name="hebi"/>
    </visual>
  </link>

  <joint name="base" type="continuous">
    <parent link="basemotor"/>
    <child  link="lbracket"/>
    <origin xyz="0 0 0.0451" rpy="0 0 -1.5708"/>  <!--0.035, 0.03321-->
    <axis   xyz="0 0 1"/>
  </joint>

  <!-- L BRACKET: Shift and rotate across the L bracket. -->
  <link name="lbracket">
    <visual>
      <origin xyz = ".085 .0550 0" rpy="1.5708 0 -1.5708"/>
      <geometry>
        <mesh filename="package://snakes_and_ladders/meshes/lower_bracket_improved_1005.STL"
        scale = "0.001 0.001 0.001"/>
      </geometry>
      <material name = "wood"/>
    </visual>
  </link>

  <joint name="lbracket" type="fixed">
    <parent link="lbracket"/>
    <child  link="shouldermotor"/>
    <origin xyz="-0.038 0.02 0.113" rpy="0 -1.5708 1.5708"/>	  <!-- L BRACKET DIMENIONS -1.5708 0.0445 -0.017 0.1025 -->
  </joint>

  <!-- SHOULDER MOTOR: Thickness: X5 = 31.1mm, X8 = 45.1mm -0.0065 -->
  <link name="shouldermotor">
    <visual>
      <origin xyz="0 0 -0.02250" rpy="0 0 0"/>
      <geometry>
        <mesh filename="package://snakes_and_ladders/meshes/X8.stl"
	      scale="0.001 0.001 0.001"/>
      </geometry>
      <material name="hebi"/>
    </visual>
  </link>

  <joint name="shoulder" type="continuous">
    <parent link="shouldermotor"/>
    <child  link="upperarm"/>
    <origin xyz="0 0 0.03225" rpy="-3.14159 0 0.02"/>
    <axis   xyz="0 0 -1"/>
  </joint>

  <!-- UPPER ARM: Shift across the upper arm (1/4in thickness) -->
  <link name="upperarm">
    <visual>
      <origin xyz="-0.034767 0.037869 0.00285" rpy="1.5708 0 0"/>  <!-- 0.25 0 0.00285 -->
      <geometry>
	      <mesh filename="package://snakes_and_ladders/meshes/Upperarm_improved.STL"
            scale="0.001 0.001 0.001"/>
      </geometry>
      <material name="wood"/>
    </visual>
    <!-- Add a visual element -->
  </link>

  <joint name="upperarm" type="fixed">
    <parent link="upperarm"/>
    <child  link="elbowmotor"/>
    <origin xyz="0.3850 -0.0025 0.0251" rpy="0 0 0"/>		  <!-- "0.3850 -0.0025 0.0057"-->
  </joint>

  <!-- Elbow motor.  Thickness: X5 = 31.1mm, X8 = 45.1mm -->
  <link name="elbowmotor">
    <visual>
      <origin xyz="-0.002 0.002 -0.0161" rpy="0 0 0"/>
      <geometry>
        <mesh filename="package://snakes_and_ladders/meshes/X5.stl"
	      scale="0.001 0.001 0.001"/>
      </geometry>
      <material name="hebi"/>
    </visual>
  </link>

  <joint name="elbow" type="continuous">
    <parent link="elbowmotor"/>
    <child  link="lowerarm"/>
    <origin xyz="0 0 0.01655" rpy="0 0 0"/>
    <axis   xyz="0 0 1"/>
  </joint>

  <!-- Shift across the upper arm (1/4in thickness) -->
  <link name="lowerarm">
    <visual>
      <origin xyz="-0.036768 0.039268 -0.00175" rpy="1.5708 0 0"/>
      <geometry>
        <mesh filename="package://snakes_and_ladders/meshes/lowerarm_improved.STL"
            scale="0.001 0.001 0.001"/>
      </geometry>
      <material name="wood"/>
    </visual>
  </link>

  <joint name="wrist_rot" type="fixed">
    <parent link="lowerarm"/>
    <child  link="wristmotor"/>
    <origin xyz="0.350 0  -0.01655" rpy="0 0 -3.14"/>		  <!-- LOWER ARM DIMENIONS 0.00285 -->
  </joint>

  <!-- Wrist motor.  Thickness: X5 = 31.1mm, X8 = 45.1mm -->
  <link name="wristmotor">
    <visual>
      <origin xyz="0.002 -0.002 0.01455" rpy="-3.14 0 0"/>
      <geometry>
        <mesh filename="package://snakes_and_ladders/meshes/X5.stl"
	      scale="0.001 0.001 0.001"/>
      </geometry>
      <material name="hebi"/>
    </visual>
  </link>

  <joint name="wrist" type="continuous">
    <parent link="wristmotor"/>
    <child  link="lowerbracket"/>
    <origin xyz="0 0 -0.0321" rpy="3.14 1.5708 0"/>
    <axis   xyz="1 0 0"/>
  </joint>

  <!-- Lower L Bracket -->
  <link name="lowerbracket">
    <visual>
      <origin xyz="-0.015 -0.0475 -0.025" rpy="0 0 0"/>  <!-- Lower L Bracket -0.0475 -->
      <geometry>
        <mesh filename="package://snakes_and_ladders/meshes/l_bracket_gripper.STL"
            scale="0.001 0.001 0.001"/>
      </geometry>
      <material name="wood"/>
    </visual>
  </link>

  <joint name="gripper" type="fixed">
    <parent link="lowerbracket"/>
    <child  link="gripper"/>
    <origin xyz="-0.0075 -0.0175 -0.055" rpy="-1.5708 -1.5708 -1.5708"/>		 
  </joint>


  <link name="gripper">
    <visual>
      <origin xyz="0.033 0.01 0.077" rpy="0 1.5708 0"/>  <!-- Lower L Bracket 0.033 -->
      <geometry>
        <mesh filename="package://snakes_and_ladders/meshes/Gripper_Part.STL"
            scale="0.001 0.001 0.001"/>
      </geometry>
      <material name="wood"/>
    </visual>
  </link>

  <joint name="revolve" type="fixed">
    <parent link="gripper"/>
    <child  link="tip"/>
    <origin xyz="0.070 0.132 0.03" rpy="0 0 0"/>		 <!-- Lower L Bracket 0.025-0.010, 0.05-0.035 -->
  </joint>
  
  <!-- TIP FRAME -->
  <link name="tip"/>

  <!-- *************************************************** -->
  <!-- *************** Visual Link Elements ************** -->
  <!-- *************************************************** -->
  <!-- Note collada .dae files have better color/texture   -->
  <!-- suppport that STL files.                            -->

  <!-- Colors -->
  <material name="wood">  <color rgba="0.82 0.62 0.04 1"/>  </material>
  <material name="hebi">  <color rgba="0.82 0.06 0.06 1"/>  </material>

</robot>
